<mujoco model="lbr_iiwa">
    <compiler angle="radian" meshdir='./kuka-allegro-meshes/'/>
    <size njmax="500" nconmax="500" />
    <option timestep="0.002"/>

    <default>
         <!-- <geom margin='0.001' solref='0.002 1' solimp='0.8 0.8 0.1'/> -->
         <!-- <motor ctrllimited="true" ctrlrange="-10 10"/> -->
         <geom friction="1 0.005 0.001" condim="3" margin="0.0005" contype="1" conaffinity="1"></geom>

         <default class="robot0:asset_class">
             <geom friction="1 0.005 0.001" condim="3" margin="0.0005" contype="1" conaffinity="1"></geom>
             <joint limited="true" damping="0.1" armature="0.001" margin="0.01" frictionloss="0.001"></joint>
             <site size="0.005" rgba="0.4 0.9 0.4 1"></site>
             <general ctrllimited="true" forcelimited="true"></general>
         </default>
    </default>

    <asset>
        <mesh name="link_0" file="link_0.stl" />
        <mesh name="link_1" file="link_1.stl" />
        <mesh name="link_2" file="link_2.stl" />
        <mesh name="link_3" file="link_3.stl" />
        <mesh name="link_4" file="link_4.stl" />
        <mesh name="link_5" file="link_5.stl" />
        <mesh name="link_6" file="link_6.stl" />
        <mesh name="link_7" file="link_7.stl" />

        <texture name="texplane" type="2d" builtin="checker" rgb1=".2 .3 .4" rgb2=".1 0.15 0.2"
            width="512" height="512"/>

        <material name='MatPlane' reflectance='0.3' texture="texplane" texrepeat="1 1" texuniform="true"/>
    </asset>
    <worldbody>

        <!-- Floor -->
        <geom name='floor' pos='0 0 -0.2' size='2 2 .01' type='plane' material="MatPlane" contype='4'/>
        <!-- Lighting -->
        <light directional='true' diffuse='.7 .7 .7'  castshadow="false"  specular='0.03 0.03 0.03' pos='-1 -1.0 4.0' dir='1 1.0 -4'/>

        <!-- Robot -->

        <geom type="mesh" rgba="0.2 0.2 0.2 1" mesh="link_0" contype='2' conaffinity='2'/>
        <body name="lbr_iiwa_link_1" pos="0 0 0.1575">
            <inertial pos="0 -0.03 0.12" mass="4" diaginertia="0.1 0.09 0.02" />
            <joint name="lbr_iiwa_joint_1" pos="0 0 0" axis="0 0 1" limited="true" range="-2.96706 2.96706" damping="0.1" armature='0.001'/>
            <geom type="mesh" rgba="0.5 0.7 1 1" mesh="link_1" />
            <body name="lbr_iiwa_link_2" pos="0 0 0.2025" quat="0 0 0.707107 0.707107">
                <inertial pos="0.0003 0.059 0.042" quat="0.707107 0.707107 0 0" mass="4" diaginertia="0.05 0.044 0.018" />
                <joint name="lbr_iiwa_joint_2" pos="0 0 0" axis="0 0 1" limited="true" range="-2.0944 2.0944" damping="0.1" armature='0.001'/>
                <geom type="mesh" rgba="0.5 0.7 1 1" mesh="link_2" />
                <body name="lbr_iiwa_link_3" pos="0 0.2045 0" quat="0 0 0.707107 0.707107">
                    <inertial pos="0 0.03 0.13" mass="3" diaginertia="0.08 0.075 0.01" />
                    <joint name="lbr_iiwa_joint_3" pos="0 0 0" axis="0 0 1" limited="true" range="-2.96706 2.96706" damping="0.1" armature='0.001'/>
                    <geom type="mesh" rgba="1 0.423529 0.0392157 1" mesh="link_3" />
                    <body name="lbr_iiwa_link_4" pos="0 0 0.2155" quat="0.707107 0.707107 0 0">
                        <inertial pos="0 0.067 0.034" quat="0.707107 0.707107 0 0" mass="2.7" diaginertia="0.03 0.029 0.01" />
                        <joint name="lbr_iiwa_joint_4" pos="0 0 0" axis="0 0 1" limited="true" range="-2.0944 2.0944" damping="0.1" armature='0.001'/>
                        <geom type="mesh" rgba="0.5 0.7 1 1" mesh="link_4" />
                        <body name="lbr_iiwa_link_5" pos="0 0.1845 0" quat="0 0 0.707107 0.707107">
                            <inertial pos="0.0001 0.021 0.076" mass="1.7" diaginertia="0.02 0.018 0.005" />
                            <joint name="lbr_iiwa_joint_5" pos="0 0 0" axis="0 0 1" limited="true" range="-2.96706 2.96706" damping="0.1" armature='0.001'/>
                            <geom type="mesh" rgba="0.5 0.7 1 1" mesh="link_5" />
                            <body name="lbr_iiwa_link_6" pos="0 0 0.2155" quat="0.707107 0.707107 0 0">
                                <inertial pos="0 0.0006 0.0004" quat="0.707107 0.707107 0 0" mass="1.8" diaginertia="0.005 0.0047 0.0036" />
                                <joint name="lbr_iiwa_joint_6" pos="0 0 0" axis="0 0 1" limited="true" range="-2.0944 2.0944" damping="0.1" armature='0.001'/>
                                <geom type="mesh" rgba="1 0.423529 0.0392157 1" mesh="link_6" />
                                <body name="lbr_iiwa_link_7" pos="0 0.081 0" quat="0 0 0.707107 0.707107">
                                    <inertial pos="0 0 0.02" mass="0.3" diaginertia="0.001 0.001 0.001" />
                                    <joint name="lbr_iiwa_joint_7" pos="0 0 0" axis="0 0 1" limited="true" range="-3.05433 3.05433" damping="0.1" armature='0.001'/>
                                    <geom type="mesh" rgba="0.2 0.2 0.2 1" mesh="link_7" />
                                    <body name='allegro-hand' euler='0 1.57 0'>
                                        <include file="allegro.xml"/>
                                    </body>
                                </body>
                            </body>
                        </body>
                    </body>
                </body>
            </body>
        </body>

        <body name="object" pos="0.5 0.2 0.2">
            <geom name="object" type="box" size="0.025 0.025 0.025" condim="4" density="567"></geom>
            <geom name="object_hidden" type="box" size="0.024 0.024 0.024" condim="4" contype="0" conaffinity="0" mass="0"></geom>
            <site name="object:center" pos="0 0 0" rgba="1 0 0 0" size="0.01 0.01 0.01"></site>
            <joint name="object:joint" type="free" damping="0.01"></joint>
        </body>
        <body name="target" pos="0.5 0.5 0.5" euler='0 1.57 0'>
            <geom name="target" type="box" size="0.025 0.025 0.025" condim="4" group="2" contype="0" conaffinity="0"></geom>
            <site name="target:center" pos="0 0 0" rgba="1 0 0 0" size="0.01 0.01 0.01"></site>
            <!-- <joint name="target:joint" type="free" damping="0.01"></joint> -->
        </body>


    </worldbody>


    <actuator>
        <!-- <motor name='index0'  gear='20' joint='index-joint-0' />
        <motor name='index1'  gear='10' joint='index-joint-1' />
        <motor name='index2'  gear='10' joint='index-joint-2' />
        <motor name='index3'  gear='10' joint='index-joint-3' />
        <motor name='middle0' gear='20'  joint='middle-joint-0' />
        <motor name='middle1' gear='10'  joint='middle-joint-1' />
        <motor name='middle2' gear='10'  joint='middle-joint-2' />
        <motor name='middle3' gear='10'  joint='middle-joint-3' />
        <motor name='pinky0'  gear='20' joint='pinky-joint-0' />
        <motor name='pinky1'  gear='10' joint='pinky-joint-1' />
        <motor name='pinky2'  gear='10' joint='pinky-joint-2' />
        <motor name='pinky3'  gear='10' joint='pinky-joint-3' />
        <motor name='thumb0'  gear='20' joint='thumb-joint-0' />
        <motor name='thumb1'  gear='10' joint='thumb-joint-1' />
        <motor name='thumb2'  gear='10' joint='thumb-joint-2' />
        <motor name='thumb3'  gear='10' joint='thumb-joint-3' /> -->

        <position name='index0'  joint='index-joint-0'   ctrlrange='-1.6 1.6'   kp='2' forcerange='-5 2'/>
        <position name='index1'  joint='index-joint-1'   ctrlrange='-0.5 2.6'      kp='2' forcerange='-5 2'/>
        <position name='index2'  joint='index-joint-2'   ctrlrange='-0.5 2.6'      kp='2' forcerange='-5 2'/>
        <position name='index3'  joint='index-joint-3'   ctrlrange='-0.5 2.6'      kp='2' forcerange='-5 2'/>
        <position name='middle0' joint='middle-joint-0'  ctrlrange='-1.6 1.6'   kp='2' forcerange='-5 2'/>
        <position name='middle1' joint='middle-joint-1'  ctrlrange='-0.5 2.6'      kp='2' forcerange='-5 2'/>
        <position name='middle2' joint='middle-joint-2'  ctrlrange='-0.5 2.6'      kp='2' forcerange='-5 2'/>
        <position name='middle3' joint='middle-joint-3'  ctrlrange='-0.5 2.6'      kp='2' forcerange='-5 2'/>
        <position name='pinky0'  joint='pinky-joint-0'   ctrlrange='-1.6 1.6'   kp='2' forcerange='-5 2'/>
        <position name='pinky1'  joint='pinky-joint-1'   ctrlrange='-0.5 2.6'      kp='2' forcerange='-5 2'/>
        <position name='pinky2'  joint='pinky-joint-2'   ctrlrange='-0.5 2.6'      kp='2' forcerange='-5 2'/>
        <position name='pinky3'  joint='pinky-joint-3'   ctrlrange='-0.5 2.6'      kp='2' forcerange='-5 2'/>
        <position name='thumb0'  joint='thumb-joint-0'   ctrlrange='-1.6 1.6'   kp='2' forcerange='-5 2'/>
        <position name='thumb1'  joint='thumb-joint-1'   ctrlrange='-0.5 2.6'      kp='2' forcerange='-5 2'/>
        <position name='thumb2'  joint='thumb-joint-2'   ctrlrange='-0.5 2.6'      kp='2' forcerange='-5 2'/>
        <position name='thumb3'  joint='thumb-joint-3'   ctrlrange='-0.5 2.6'      kp='2' forcerange='-5 2'/>

        <!-- <position name="index0" class="robot0:asset_class" user="2038" joint="index-joint-0" ctrlrange="-0.489 0.14" kp="5" forcerange="-4.785 4.785"></position>
        <position name="index1" class="robot0:asset_class" user="2036" joint="index-joint-1" ctrlrange="-0.698 0.489" kp="5" forcerange="-2.175 2.175"></position>
        <position name="index2" class="robot0:asset_class" user="2004" joint="index-joint-2" ctrlrange="-0.349 0.349" kp="1" forcerange="-0.9 0.9"></position>
        <position name="index3" class="robot0:asset_class" user="2002" joint="index-joint-3" ctrlrange="0 1.571" kp="1" forcerange="-0.9 0.9"></position> -->



        <motor name='joint_1' gear='220'  joint='lbr_iiwa_joint_1' />
        <motor name='joint_2' gear='220'  joint='lbr_iiwa_joint_2' />
        <motor name='joint_3' gear='120'  joint='lbr_iiwa_joint_3' />
        <motor name='joint_4' gear='100'  joint='lbr_iiwa_joint_4' />
        <motor name='joint_5' gear='80'  joint='lbr_iiwa_joint_5' />
        <motor name='joint_6' gear='10'  joint='lbr_iiwa_joint_6' />
        <motor name='joint_7' gear='10'  joint='lbr_iiwa_joint_7' />
        <!-- <velocity name='joint_1' kv='4'  joint='lbr_iiwa_joint_1' />
        <velocity name='joint_2' kv='4'  joint='lbr_iiwa_joint_2' />
        <velocity name='joint_3' kv='4'  joint='lbr_iiwa_joint_3' />
        <velocity name='joint_4' kv='4'  joint='lbr_iiwa_joint_4' />
        <velocity name='joint_5' kv='4' joint='lbr_iiwa_joint_5' />
        <velocity name='joint_6' kv='4' joint='lbr_iiwa_joint_6' />
        <velocity name='joint_7' kv='2' joint='lbr_iiwa_joint_7' /> -->
    </actuator>


    <sensor>
        <framepos name='palm-pos' objtype='site' objname='allegro:palm'/>
        <framepos name='target-pos' objtype='site' objname='target:center'/>
        <framepos name='obj-pos' objtype='site' objname='object:center'/>

        <jointpos name='index0'  joint='index-joint-0' />
        <jointpos name='index1'  joint='index-joint-1' />
        <jointpos name='index2'  joint='index-joint-2' />
        <jointpos name='index3'  joint='index-joint-3' />
        <jointpos name='middle0'  joint='middle-joint-0' />
        <jointpos name='middle1'  joint='middle-joint-1' />
        <jointpos name='middle2'  joint='middle-joint-2' />
        <jointpos name='middle3'  joint='middle-joint-3' />
        <jointpos name='pinky0'  joint='pinky-joint-0' />
        <jointpos name='pinky1'  joint='pinky-joint-1' />
        <jointpos name='pinky2'  joint='pinky-joint-2' />
        <jointpos name='pinky3'  joint='pinky-joint-3' />
        <jointpos name='thumb0'  joint='thumb-joint-0' />
        <jointpos name='thumb1'  joint='thumb-joint-1' />
        <jointpos name='thumb2'  joint='thumb-joint-2' />
        <jointpos name='thumb3'  joint='thumb-joint-3' />
        <jointpos name='joint_1'  joint='lbr_iiwa_joint_1' />
        <jointpos name='joint_2'  joint='lbr_iiwa_joint_2' />
        <jointpos name='joint_3'  joint='lbr_iiwa_joint_3' />
        <jointpos name='joint_4'  joint='lbr_iiwa_joint_4' />
        <jointpos name='joint_5'  joint='lbr_iiwa_joint_5' />
        <jointpos name='joint_6'  joint='lbr_iiwa_joint_6' />
        <jointpos name='joint_7'  joint='lbr_iiwa_joint_7' />

        <jointvel name='vel-index0'  joint='index-joint-0' />
        <jointvel name='vel-index1'  joint='index-joint-1' />
        <jointvel name='vel-index2'  joint='index-joint-2' />
        <jointvel name='vel-index3'  joint='index-joint-3' />
        <jointvel name='vel-middle0'  joint='middle-joint-0' />
        <jointvel name='vel-middle1'  joint='middle-joint-1' />
        <jointvel name='vel-middle2'  joint='middle-joint-2' />
        <jointvel name='vel-middle3'  joint='middle-joint-3' />
        <jointvel name='vel-pinky0'  joint='pinky-joint-0' />
        <jointvel name='vel-pinky1'  joint='pinky-joint-1' />
        <jointvel name='vel-pinky2'  joint='pinky-joint-2' />
        <jointvel name='vel-pinky3'  joint='pinky-joint-3' />
        <jointvel name='vel-thumb0'  joint='thumb-joint-0' />
        <jointvel name='vel-thumb1'  joint='thumb-joint-1' />
        <jointvel name='vel-thumb2'  joint='thumb-joint-2' />
        <jointvel name='vel-thumb3'  joint='thumb-joint-3' />
        <jointvel name='vel-joint_1'  joint='lbr_iiwa_joint_1' />
        <jointvel name='vel-joint_2'  joint='lbr_iiwa_joint_2' />
        <jointvel name='vel-joint_3'  joint='lbr_iiwa_joint_3' />
        <jointvel name='vel-joint_4'  joint='lbr_iiwa_joint_4' />
        <jointvel name='vel-joint_5'  joint='lbr_iiwa_joint_5' />
        <jointvel name='vel-joint_6'  joint='lbr_iiwa_joint_6' />
        <jointvel name='vel-joint_7'  joint='lbr_iiwa_joint_7' />

    </sensor>


</mujoco>
