<mujoco model='Franka-door'>

    <option gravity='0 0 0'/>
    <default>
         <geom margin='0.001' solref='0.002 1' solimp='0.8 0.8 0.1'/>
    </default>

    <compiler inertiafromgeom='true' angle='radian' meshdir="meshes/"/>

    <include file="franka-assets.xml"/>

    <worldbody>
        <!-- Floor -->
        <geom name='floor' pos='0 0 0' size='2 2 .01' type='plane' material="MatPlane" contype='4'/>
        <!-- Lighting -->
        <light directional='false' diffuse='.7 .7 .7' specular='0.03 0.03 0.03' pos='-1 -1.0 4.0' dir='1 1.0 -4'/>

        <!-- Robot -->
        <body name="robot" pos="0.1 0.5 0">
            <include file="franka.xml"/>
        </body>
        <!-- Door -->
        <!-- <body name='Door' pos='0.85 0.2 0.51' euler='0 0 0' user="1001 0 2002 -0.4 -0.1 0.252 0 0.3 0.45"> -->
        <body name='handle' pos='0.6 0.2 0.31' euler='0 0 0'  user="1001 0 2002 -0.4 -0.1 0.252 0 0.3 0.45">
            <inertial pos='0 0 0' mass='0.2' />
            <joint name='articulation' pos='0 0.3 0' axis='1 0 0' type='slide' range='-0.4 0.01' frictionloss='1'/>
            <!-- <geom name='box' type='cylinder' size='0.2 0.01 0.01' euler='0 1.57 0'/> -->
            <geom name='handle' type='cylinder' size='0.01 0.2 0.01' pos='0 0 0' euler='1.57 0 0'/>
            <site name='handle' pos='0 0 0' size='0.02' rgba='0 1 0 0.125'/>
        </body>


    </worldbody>


    <sensor>

        <framequat name='gripper_rot' objtype='site' objname='grasp'/>
        <framepos name='gripper_pos' objtype='site' objname='grasp'/>
        <framepos name='handle-pos' objtype='body' objname='handle'/>

    </sensor>

</mujoco>
